[2025-01-31T03:53:03.717+0000] {taskinstance.py:1159} INFO - Dependencies all met for dep_context=non-requeueable deps ti=<TaskInstance: example_passing_params_via_test_command.also_run_this scheduled__2025-01-31T03:52:00+00:00 [queued]>
[2025-01-31T03:53:03.739+0000] {taskinstance.py:1159} INFO - Dependencies all met for dep_context=requeueable deps ti=<TaskInstance: example_passing_params_via_test_command.also_run_this scheduled__2025-01-31T03:52:00+00:00 [queued]>
[2025-01-31T03:53:03.741+0000] {taskinstance.py:1361} INFO - Starting attempt 1 of 1
[2025-01-31T03:53:03.792+0000] {taskinstance.py:1382} INFO - Executing <Task(BashOperator): also_run_this> on 2025-01-31 03:52:00+00:00
[2025-01-31T03:53:03.808+0000] {standard_task_runner.py:57} INFO - Started process 799 to run task
[2025-01-31T03:53:03.819+0000] {standard_task_runner.py:84} INFO - Running: ['***', 'tasks', 'run', 'example_passing_params_via_test_command', 'also_run_this', 'scheduled__2025-01-31T03:52:00+00:00', '--job-id', '226', '--raw', '--subdir', '/home/***/.local/lib/python3.8/site-packages/***/example_dags/example_passing_params_via_test_command.py', '--cfg-path', '/tmp/tmpr22qv8fl']
[2025-01-31T03:53:03.828+0000] {standard_task_runner.py:85} INFO - Job 226: Subtask also_run_this
[2025-01-31T03:53:04.005+0000] {task_command.py:415} INFO - Running <TaskInstance: example_passing_params_via_test_command.also_run_this scheduled__2025-01-31T03:52:00+00:00 [running]> on host dc644052abf1
[2025-01-31T03:53:04.157+0000] {abstractoperator.py:696} ERROR - Exception rendering Jinja template for task 'also_run_this', field 'env'. Template: {'FOO': '{{ params.foo }}', 'MIFF': '{{ params.miff }}'}
Traceback (most recent call last):
  File "/home/airflow/.local/lib/python3.8/site-packages/airflow/models/abstractoperator.py", line 688, in _do_render_template_fields
    rendered_content = self.render_template(
  File "/home/airflow/.local/lib/python3.8/site-packages/airflow/template/templater.py", line 168, in render_template
    return {k: self.render_template(v, context, jinja_env, oids) for k, v in value.items()}
  File "/home/airflow/.local/lib/python3.8/site-packages/airflow/template/templater.py", line 168, in <dictcomp>
    return {k: self.render_template(v, context, jinja_env, oids) for k, v in value.items()}
  File "/home/airflow/.local/lib/python3.8/site-packages/airflow/template/templater.py", line 156, in render_template
    return self._render(template, context)
  File "/home/airflow/.local/lib/python3.8/site-packages/airflow/models/abstractoperator.py", line 642, in _render
    return super()._render(template, context, dag=dag)
  File "/home/airflow/.local/lib/python3.8/site-packages/airflow/template/templater.py", line 113, in _render
    return render_template_to_string(template, context)
  File "/home/airflow/.local/lib/python3.8/site-packages/airflow/utils/helpers.py", line 289, in render_template_to_string
    return render_template(template, cast(MutableMapping[str, Any], context), native=False)
  File "/home/airflow/.local/lib/python3.8/site-packages/airflow/utils/helpers.py", line 284, in render_template
    return "".join(nodes)
  File "<template>", line 12, in root
  File "/home/airflow/.local/lib/python3.8/site-packages/jinja2/runtime.py", line 852, in _fail_with_undefined_error
    raise self._undefined_exception(self._undefined_message)
jinja2.exceptions.UndefinedError: 'dict object' has no attribute 'foo'
[2025-01-31T03:53:04.195+0000] {taskinstance.py:1943} ERROR - Task failed with exception
Traceback (most recent call last):
  File "/home/airflow/.local/lib/python3.8/site-packages/airflow/models/taskinstance.py", line 1518, in _run_raw_task
    self._execute_task_with_callbacks(context, test_mode, session=session)
  File "/home/airflow/.local/lib/python3.8/site-packages/airflow/models/taskinstance.py", line 1646, in _execute_task_with_callbacks
    task_orig = self.render_templates(context=context)
  File "/home/airflow/.local/lib/python3.8/site-packages/airflow/models/taskinstance.py", line 2291, in render_templates
    original_task.render_template_fields(context)
  File "/home/airflow/.local/lib/python3.8/site-packages/airflow/models/baseoperator.py", line 1244, in render_template_fields
    self._do_render_template_fields(self, self.template_fields, context, jinja_env, set())
  File "/home/airflow/.local/lib/python3.8/site-packages/airflow/utils/session.py", line 77, in wrapper
    return func(*args, session=session, **kwargs)
  File "/home/airflow/.local/lib/python3.8/site-packages/airflow/models/abstractoperator.py", line 688, in _do_render_template_fields
    rendered_content = self.render_template(
  File "/home/airflow/.local/lib/python3.8/site-packages/airflow/template/templater.py", line 168, in render_template
    return {k: self.render_template(v, context, jinja_env, oids) for k, v in value.items()}
  File "/home/airflow/.local/lib/python3.8/site-packages/airflow/template/templater.py", line 168, in <dictcomp>
    return {k: self.render_template(v, context, jinja_env, oids) for k, v in value.items()}
  File "/home/airflow/.local/lib/python3.8/site-packages/airflow/template/templater.py", line 156, in render_template
    return self._render(template, context)
  File "/home/airflow/.local/lib/python3.8/site-packages/airflow/models/abstractoperator.py", line 642, in _render
    return super()._render(template, context, dag=dag)
  File "/home/airflow/.local/lib/python3.8/site-packages/airflow/template/templater.py", line 113, in _render
    return render_template_to_string(template, context)
  File "/home/airflow/.local/lib/python3.8/site-packages/airflow/utils/helpers.py", line 289, in render_template_to_string
    return render_template(template, cast(MutableMapping[str, Any], context), native=False)
  File "/home/airflow/.local/lib/python3.8/site-packages/airflow/utils/helpers.py", line 284, in render_template
    return "".join(nodes)
  File "<template>", line 12, in root
  File "/home/airflow/.local/lib/python3.8/site-packages/jinja2/runtime.py", line 852, in _fail_with_undefined_error
    raise self._undefined_exception(self._undefined_message)
jinja2.exceptions.UndefinedError: 'dict object' has no attribute 'foo'
[2025-01-31T03:53:04.223+0000] {taskinstance.py:1400} INFO - Marking task as FAILED. dag_id=example_passing_params_via_test_command, task_id=also_run_this, execution_date=20250131T035200, start_date=20250131T035303, end_date=20250131T035304
[2025-01-31T03:53:04.257+0000] {standard_task_runner.py:104} ERROR - Failed to execute job 226 for task also_run_this ('dict object' has no attribute 'foo'; 799)
[2025-01-31T03:53:04.316+0000] {local_task_job_runner.py:228} INFO - Task exited with return code 1
[2025-01-31T03:53:04.863+0000] {taskinstance.py:2784} INFO - 0 downstream tasks scheduled from follow-on schedule check
